Workbook

Sheet Dashboard Manager
A1: TARGET BULANAN | B1: REALISASI OMZET (MTD) | C1: % CAPAIAN TARGET | D1: SISA TARGET | E1: TOTAL PORSI / CUP | G1: KONTROL STRATEGI MENU (MENU ENGINEERING) | O1: Tanggal | P1: Omzet Harian | Q1: Nama Menu | R1: Qty Terjual | S1: Kategori | T1: Total Pengeluaran
A2: 60000000 | B2: {=SUMIF(Calc_Data!F:F, TEXT(IF(DAY(INDEX(O2:O15, COUNTA(O2:O15)))>=7, INDEX(O2:O15, COUNTA(O2:O15)), EDATE(INDEX(O2:O15, COUNTA(O2:O15)), -1)), "yyyy-mm") & " (Tgl 7-6)", Calc_Data!B:B)} -> 5602500 | C2: =B2/A2 -> 0.093375 | D2: =MAX(0, A2-B2) -> 54397500 | E2: =SUM('Drop Data Kasir'!B:B) -> 480 | G2: ⭐ STAR | H2: 🧩 PUZZLE | K2: 🐎 WORKHORSE | L2: 🐕 DOG | O2: =IFERROR(__xludf.DUMMYFUNCTION("SORT(QUERY(Calc_Data!A2:B100, ""SELECT A, B WHERE A IS NOT NULL AND B > 0 ORDER BY A DESC LIMIT 14"", 0), 1, TRUE)"),46261.0) -> 46261 | P2: =IFERROR(__xludf.DUMMYFUNCTION("""COMPUTED_VALUE"""),1104000.0) -> 1104000 | Q2: =IFERROR(__xludf.DUMMYFUNCTION("QUERY({'Drop Data Kasir'!A2:A100 , 'Drop Data Kasir'!B2:B100 , 'Drop Data Kasir'!C2:C100}, ""SELECT Col1, SUM(Col2) WHERE Col3 = date '"" & TEXT(MAX('Drop Data Kasir'!C2:C100), ""yyyy-mm-dd"") & ""' GROUP BY Col1 ORDER BY SUM(Col2) DESC LIMIT 5 LABEL Col1"&" '', SUM(Col2) ''"", 0)"),"Nasi Goreng Kara") -> Nasi Goreng Kara | R2: =IFERROR(__xludf.DUMMYFUNCTION("""COMPUTED_VALUE"""),5.0) -> 5 | S2: =IFERROR(__xludf.DUMMYFUNCTION("QUERY('Log Pengeluaran'!C5:E100, ""SELECT C, SUM(E) WHERE C IS NOT NULL AND C <> '' AND LOWER(C) <> 'prive' GROUP BY C ORDER BY SUM(E) DESC LABEL C '', SUM(E) ''"", 0)"),"Gaji") -> Gaji | T2: =IFERROR(__xludf.DUMMYFUNCTION("""COMPUTED_VALUE"""),4860000.0) -> 4860000
A3: Target Toko Rp 60 Jt | B3: Periode Berjalan (Siklus Tgl 7-6) | C3: Pencapaian vs Target | D3: Kekurangan Omzet Toko | E3: Volume Penjualan MTD | G3: ='Analisis Menu Engineering'!C7 -> 8 Menu | H3: ='Analisis Menu Engineering'!G7 -> 12 Menu | K3: ='Analisis Menu Engineering'!E7 -> 8 Menu | L3: ='Analisis Menu Engineering'!I7 -> 11 Menu | O3: =IFERROR(__xludf.DUMMYFUNCTION("""COMPUTED_VALUE"""),46262.0) -> 46262 | P3: =IFERROR(__xludf.DUMMYFUNCTION("""COMPUTED_VALUE"""),1557000.0) -> 1557000 | Q3: =IFERROR(__xludf.DUMMYFUNCTION("""COMPUTED_VALUE"""),"Cappucino") -> Cappucino | R3: =IFERROR(__xludf.DUMMYFUNCTION("""COMPUTED_VALUE"""),4.0) -> 4 | S3: =IFERROR(__xludf.DUMMYFUNCTION("""COMPUTED_VALUE"""),"Bahan Baku") -> Bahan Baku | T3: =IFERROR(__xludf.DUMMYFUNCTION("""COMPUTED_VALUE"""),3424500.0) -> 3424500
G4: Margin Tinggi • Laris | H4: Margin Tinggi • Sepi | K4: Margin Rendah • Laris | L4: Margin Rendah • Sepi | O4: =IFERROR(__xludf.DUMMYFUNCTION("""COMPUTED_VALUE"""),46263.0) -> 46263 | P4: =IFERROR(__xludf.DUMMYFUNCTION("""COMPUTED_VALUE"""),2202500.0) -> 2202500 | Q4: =IFERROR(__xludf.DUMMYFUNCTION("""COMPUTED_VALUE"""),"Cikalopi") -> Cikalopi | R4: =IFERROR(__xludf.DUMMYFUNCTION("""COMPUTED_VALUE"""),3.0) -> 3 | S4: =IFERROR(__xludf.DUMMYFUNCTION("""COMPUTED_VALUE"""),"Operasional") -> Operasional | T4: =IFERROR(__xludf.DUMMYFUNCTION("""COMPUTED_VALUE"""),1451000.0) -> 1451000
G5: MISI UPSELLING KASIR & BARISTA HARI INI | K5: MENU PANTAUAN TAKARAN & PORSI (WORKHORSE) | O5: =IFERROR(__xludf.DUMMYFUNCTION("""COMPUTED_VALUE"""),46264.0) -> 46264 | P5: =IFERROR(__xludf.DUMMYFUNCTION("""COMPUTED_VALUE"""),1232500.0) -> 1232500 | Q5: =IFERROR(__xludf.DUMMYFUNCTION("""COMPUTED_VALUE"""),"Kopi Nenek") -> Kopi Nenek | R5: =IFERROR(__xludf.DUMMYFUNCTION("""COMPUTED_VALUE"""),3.0) -> 3 | S5: =IFERROR(__xludf.DUMMYFUNCTION("""COMPUTED_VALUE"""),"Lain-lain") -> Lain-lain | T5: =IFERROR(__xludf.DUMMYFUNCTION("""COMPUTED_VALUE"""),405000.0) -> 405000
A6: Target Harian Rata-rata | B6: Omzet Harian Terakhir | C6: % Pencapaian Harian | D6: Gap / Selisih | E6: Status Harian | G6: Wajib ditawarkan kasir sebagai menu rekomendasi utama | K6: Margin tipis tapi laris, pastikan gramasi bahan baku tidak over-portioning | O6: =IFERROR(__xludf.DUMMYFUNCTION("""COMPUTED_VALUE"""),46265.0) -> 46265 | P6: =IFERROR(__xludf.DUMMYFUNCTION("""COMPUTED_VALUE"""),1457500.0) -> 1457500 | Q6: =IFERROR(__xludf.DUMMYFUNCTION("""COMPUTED_VALUE"""),"Pure chocolade") -> Pure chocolade | R6: =IFERROR(__xludf.DUMMYFUNCTION("""COMPUTED_VALUE"""),3.0) -> 3 | S6: =IFERROR(__xludf.DUMMYFUNCTION("""COMPUTED_VALUE"""),"Pemasaran") -> Pemasaran | T6: =IFERROR(__xludf.DUMMYFUNCTION("""COMPUTED_VALUE"""),110000.0) -> 110000
A7: =A2/30 -> 2000000 | B7: {=INDEX(P2:P15, COUNTA(P2:P15))} -> 1039000 | C7: =B7/A7 -> 0.5195 | D7: =B7-A7 -> -961000 | E7: =IF(C7>=1, "TARGET TERCAPAI", "DI BAWAH TARGET") -> DI BAWAH TARGET | G7: Nama Menu Rekomendasi | H7: Kuadran | I7: Margin Laba | K7: Nama Menu Workhorse | L7: Porsi Terjual | M7: Margin Laba | O7: =IFERROR(__xludf.DUMMYFUNCTION("""COMPUTED_VALUE"""),46266.0) -> 46266 | P7: =IFERROR(__xludf.DUMMYFUNCTION("""COMPUTED_VALUE"""),984500.0) -> 984500
A8: Dasar: Rp 60 Jt / 30 Hari | B8: {="Tanggal: " & TEXT(INDEX(O2:O15, COUNTA(O2:O15)), "yyyy-mm-dd")} -> Tanggal: 2026-09-09 | C8: Realisasi vs Target Harian | D8: Selisih vs Target Rp 2 Jt | E8: =IF(C7>=1, "Kinerja Prima", "Perlu Dorong Upselling") -> Perlu Dorong Upselling | G8: =IFERROR(__xludf.DUMMYFUNCTION("QUERY('Analisis Menu Engineering'!A9:I47, ""SELECT A, I, E WHERE I = 'Star' OR I = 'Puzzle' ORDER BY I DESC, E DESC"", 0)"),"Teh puncak Jamus") -> Teh puncak Jamus | H8: =IFERROR(__xludf.DUMMYFUNCTION("""COMPUTED_VALUE"""),"Star") -> Star | I8: =IFERROR(__xludf.DUMMYFUNCTION("""COMPUTED_VALUE"""),0.982) -> 0.982 | K8: =IFERROR(__xludf.DUMMYFUNCTION("QUERY('Analisis Menu Engineering'!A9:I47, ""SELECT A, F, E WHERE I = 'Workhorse' ORDER BY F DESC"", 0)"),"Sexy Lady") -> Sexy Lady | L8: =IFERROR(__xludf.DUMMYFUNCTION("""COMPUTED_VALUE"""),183.0) -> 183 | M8: =IFERROR(__xludf.DUMMYFUNCTION("""COMPUTED_VALUE"""),0.716) -> 0.716 | O8: =IFERROR(__xludf.DUMMYFUNCTION("""COMPUTED_VALUE"""),46267.0) -> 46267 | P8: =IFERROR(__xludf.DUMMYFUNCTION("""COMPUTED_VALUE"""),1052000.0) -> 1052000
G9: =IFERROR(__xludf.DUMMYFUNCTION("""COMPUTED_VALUE"""),"Teh Belanda") -> Teh Belanda | H9: =IFERROR(__xludf.DUMMYFUNCTION("""COMPUTED_VALUE"""),"Star") -> Star | I9: =IFERROR(__xludf.DUMMYFUNCTION("""COMPUTED_VALUE"""),0.9740740740740741) -> 0.97407407 | K9: =IFERROR(__xludf.DUMMYFUNCTION("""COMPUTED_VALUE"""),"Nasi Goreng Kara") -> Nasi Goreng Kara | L9: =IFERROR(__xludf.DUMMYFUNCTION("""COMPUTED_VALUE"""),146.0) -> 146 | M9: =IFERROR(__xludf.DUMMYFUNCTION("""COMPUTED_VALUE"""),0.6832) -> 0.6832 | O9: =IFERROR(__xludf.DUMMYFUNCTION("""COMPUTED_VALUE"""),46268.0) -> 46268 | P9: =IFERROR(__xludf.DUMMYFUNCTION("""COMPUTED_VALUE"""),775000.0) -> 775000
A10: No | B10: Nama Menu Terlaris (Tanggal Terakhir) | C10: Porsi Terjual | D10: Harga Satuan | E10: Total Omzet Menu | G10: =IFERROR(__xludf.DUMMYFUNCTION("""COMPUTED_VALUE"""),"Sweety hazy") -> Sweety hazy | H10: =IFERROR(__xludf.DUMMYFUNCTION("""COMPUTED_VALUE"""),"Star") -> Star | I10: =IFERROR(__xludf.DUMMYFUNCTION("""COMPUTED_VALUE"""),0.8348275862068966) -> 0.83482759 | K10: =IFERROR(__xludf.DUMMYFUNCTION("""COMPUTED_VALUE"""),"Latte Ice") -> Latte Ice | L10: =IFERROR(__xludf.DUMMYFUNCTION("""COMPUTED_VALUE"""),137.0) -> 137 | M10: =IFERROR(__xludf.DUMMYFUNCTION("""COMPUTED_VALUE"""),0.694) -> 0.694 | O10: =IFERROR(__xludf.DUMMYFUNCTION("""COMPUTED_VALUE"""),46269.0) -> 46269 | P10: =IFERROR(__xludf.DUMMYFUNCTION("""COMPUTED_VALUE"""),1001500.0) -> 1001500
A11: 1 | B11: =Q2 -> Nasi Goreng Kara | C11: =R2 -> 5 | D11: =IFERROR(VLOOKUP(B11, 'Master Menu'!B:C, 2, FALSE), 0) -> 25000 | E11: =C11*D11 -> 125000 | G11: =IFERROR(__xludf.DUMMYFUNCTION("""COMPUTED_VALUE"""),"Pure Chocolade") -> Pure Chocolade | H11: =IFERROR(__xludf.DUMMYFUNCTION("""COMPUTED_VALUE"""),"Star") -> Star | I11: =IFERROR(__xludf.DUMMYFUNCTION("""COMPUTED_VALUE"""),0.8206896551724138) -> 0.82068966 | K11: =IFERROR(__xludf.DUMMYFUNCTION("""COMPUTED_VALUE"""),"Party Plate") -> Party Plate | L11: =IFERROR(__xludf.DUMMYFUNCTION("""COMPUTED_VALUE"""),122.0) -> 122 | M11: =IFERROR(__xludf.DUMMYFUNCTION("""COMPUTED_VALUE"""),0.4819) -> 0.4819 | O11: =IFERROR(__xludf.DUMMYFUNCTION("""COMPUTED_VALUE"""),46270.0) -> 46270 | P11: =IFERROR(__xludf.DUMMYFUNCTION("""COMPUTED_VALUE"""),1140500.0) -> 1140500
A12: 2 | B12: =Q3 -> Cappucino | C12: =R3 -> 4 | D12: =IFERROR(VLOOKUP(B12, 'Master Menu'!B:C, 2, FALSE), 0) -> 25000 | E12: =C12*D12 -> 100000 | G12: =IFERROR(__xludf.DUMMYFUNCTION("""COMPUTED_VALUE"""),"Air mineral besar") -> Air mineral besar | H12: =IFERROR(__xludf.DUMMYFUNCTION("""COMPUTED_VALUE"""),"Star") -> Star | I12: =IFERROR(__xludf.DUMMYFUNCTION("""COMPUTED_VALUE"""),0.8114285714285714) -> 0.81142857 | K12: =IFERROR(__xludf.DUMMYFUNCTION("""COMPUTED_VALUE"""),"americano") -> americano | L12: =IFERROR(__xludf.DUMMYFUNCTION("""COMPUTED_VALUE"""),91.0) -> 91 | M12: =IFERROR(__xludf.DUMMYFUNCTION("""COMPUTED_VALUE"""),0.7111111111111111) -> 0.71111111 | O12: =IFERROR(__xludf.DUMMYFUNCTION("""COMPUTED_VALUE"""),46271.0) -> 46271 | P12: =IFERROR(__xludf.DUMMYFUNCTION("""COMPUTED_VALUE"""),1864000.0) -> 1864000
A13: 3 | B13: =Q4 -> Cikalopi | C13: =R4 -> 3 | D13: =IFERROR(VLOOKUP(B13, 'Master Menu'!B:C, 2, FALSE), 0) -> 33000 | E13: =C13*D13 -> 99000 | G13: =IFERROR(__xludf.DUMMYFUNCTION("""COMPUTED_VALUE"""),"Sour tea") -> Sour tea | H13: =IFERROR(__xludf.DUMMYFUNCTION("""COMPUTED_VALUE"""),"Star") -> Star | I13: =IFERROR(__xludf.DUMMYFUNCTION("""COMPUTED_VALUE"""),0.8074210526315789) -> 0.80742105 | K13: =IFERROR(__xludf.DUMMYFUNCTION("""COMPUTED_VALUE"""),"Mie Yabi") -> Mie Yabi | L13: =IFERROR(__xludf.DUMMYFUNCTION("""COMPUTED_VALUE"""),73.0) -> 73 | M13: =IFERROR(__xludf.DUMMYFUNCTION("""COMPUTED_VALUE"""),0.7048) -> 0.7048 | O13: =IFERROR(__xludf.DUMMYFUNCTION("""COMPUTED_VALUE"""),46272.0) -> 46272 | P13: =IFERROR(__xludf.DUMMYFUNCTION("""COMPUTED_VALUE"""),2828000.0) -> 2828000
A14: 4 | B14: =Q5 -> Kopi Nenek | C14: =R5 -> 3 | D14: =IFERROR(VLOOKUP(B14, 'Master Menu'!B:C, 2, FALSE), 0) -> 9000 | E14: =C14*D14 -> 27000 | G14: =IFERROR(__xludf.DUMMYFUNCTION("""COMPUTED_VALUE"""),"Curly Fries") -> Curly Fries | H14: =IFERROR(__xludf.DUMMYFUNCTION("""COMPUTED_VALUE"""),"Star") -> Star | I14: =IFERROR(__xludf.DUMMYFUNCTION("""COMPUTED_VALUE"""),0.7963636363636364) -> 0.79636364 | K14: =IFERROR(__xludf.DUMMYFUNCTION("""COMPUTED_VALUE"""),"Latte") -> Latte | L14: =IFERROR(__xludf.DUMMYFUNCTION("""COMPUTED_VALUE"""),64.0) -> 64 | M14: =IFERROR(__xludf.DUMMYFUNCTION("""COMPUTED_VALUE"""),0.694) -> 0.694 | O14: =IFERROR(__xludf.DUMMYFUNCTION("""COMPUTED_VALUE"""),46273.0) -> 46273 | P14: =IFERROR(__xludf.DUMMYFUNCTION("""COMPUTED_VALUE"""),1735500.0) -> 1735500
A15: 5 | B15: =Q6 -> Pure chocolade | C15: =R6 -> 3 | D15: =IFERROR(VLOOKUP(B15, 'Master Menu'!B:C, 2, FALSE), 0) -> 29000 | E15: =C15*D15 -> 87000 | G15: =IFERROR(__xludf.DUMMYFUNCTION("""COMPUTED_VALUE"""),"Kopi Nenek") -> Kopi Nenek | H15: =IFERROR(__xludf.DUMMYFUNCTION("""COMPUTED_VALUE"""),"Star") -> Star | I15: =IFERROR(__xludf.DUMMYFUNCTION("""COMPUTED_VALUE"""),0.7401111111111112) -> 0.74011111 | K15: =IFERROR(__xludf.DUMMYFUNCTION("""COMPUTED_VALUE"""),"Natie Matcha") -> Natie Matcha | L15: =IFERROR(__xludf.DUMMYFUNCTION("""COMPUTED_VALUE"""),59.0) -> 59 | M15: =IFERROR(__xludf.DUMMYFUNCTION("""COMPUTED_VALUE"""),0.6052631578947368) -> 0.60526316 | O15: =IFERROR(__xludf.DUMMYFUNCTION("""COMPUTED_VALUE"""),46274.0) -> 46274 | P15: =IFERROR(__xludf.DUMMYFUNCTION("""COMPUTED_VALUE"""),1039000.0) -> 1039000
G16: =IFERROR(__xludf.DUMMYFUNCTION("""COMPUTED_VALUE"""),"Claudio (Vanilla)") -> Claudio (Vanilla) | H16: =IFERROR(__xludf.DUMMYFUNCTION("""COMPUTED_VALUE"""),"Puzzle") -> Puzzle | I16: =IFERROR(__xludf.DUMMYFUNCTION("""COMPUTED_VALUE"""),0.8923076923076924) -> 0.89230769
A17: Tanggal | B17: Nama Karyawan | C17: Kategori Laporan | D17: Deskripsi Kejadian | E17: Tindakan / Sanksi | G17: =IFERROR(__xludf.DUMMYFUNCTION("""COMPUTED_VALUE"""),"Ivada (Stroberi)") -> Ivada (Stroberi) | H17: =IFERROR(__xludf.DUMMYFUNCTION("""COMPUTED_VALUE"""),"Puzzle") -> Puzzle | I17: =IFERROR(__xludf.DUMMYFUNCTION("""COMPUTED_VALUE"""),0.8923076923076924) -> 0.89230769 | K17: MENU EVALUASI / SLOW-MOVING (DOG)
A18: =IFERROR(__xludf.DUMMYFUNCTION("IFERROR(CHOOSEROWS(FILTER('Log Laporan Insiden'!A2:E100, 'Log Laporan Insiden'!A2:A100 <> """"), -1, -2, -3), ""Tidak ada data insiden"")"),46243.0) -> 46243 | B18: =IFERROR(__xludf.DUMMYFUNCTION("""COMPUTED_VALUE"""),"gala") -> gala | C18: =IFERROR(__xludf.DUMMYFUNCTION("""COMPUTED_VALUE"""),"Keterlambatan") -> Keterlambatan | D18: =IFERROR(__xludf.DUMMYFUNCTION("""COMPUTED_VALUE"""),"sering terlambat ") -> sering terlambat | E18: =IFERROR(__xludf.DUMMYFUNCTION("""COMPUTED_VALUE"""),"sp1") -> sp1 | G18: =IFERROR(__xludf.DUMMYFUNCTION("""COMPUTED_VALUE"""),"Vicenzo (Coklat)") -> Vicenzo (Coklat) | H18: =IFERROR(__xludf.DUMMYFUNCTION("""COMPUTED_VALUE"""),"Puzzle") -> Puzzle | I18: =IFERROR(__xludf.DUMMYFUNCTION("""COMPUTED_VALUE"""),0.8923076923076924) -> 0.89230769 | K18: Penjualan di bawah benchmark, evaluasi resep atau ganti menu
A19: =IFERROR(__xludf.DUMMYFUNCTION("""COMPUTED_VALUE"""),"08-31-2026") -> 08-31-2026 | B19: =IFERROR(__xludf.DUMMYFUNCTION("""COMPUTED_VALUE"""),"adi") -> adi | C19: =IFERROR(__xludf.DUMMYFUNCTION("""COMPUTED_VALUE"""),"Pelanggaran SOP") -> Pelanggaran SOP | D19: =IFERROR(__xludf.DUMMYFUNCTION("""COMPUTED_VALUE"""),"listrik tidak di cek") -> listrik tidak di cek | E19: =IFERROR(__xludf.DUMMYFUNCTION("""COMPUTED_VALUE"""),"sp2") -> sp2 | G19: =IFERROR(__xludf.DUMMYFUNCTION("""COMPUTED_VALUE"""),"Capri ijz (Campur)") -> Capri ijz (Campur) | H19: =IFERROR(__xludf.DUMMYFUNCTION("""COMPUTED_VALUE"""),"Puzzle") -> Puzzle | I19: =IFERROR(__xludf.DUMMYFUNCTION("""COMPUTED_VALUE"""),0.8923076923076924) -> 0.89230769 | K19: Nama Menu Dog | L19: Porsi Terjual | M19: Margin Laba
A20: =IFERROR(__xludf.DUMMYFUNCTION("""COMPUTED_VALUE"""),"08-23-2026") -> 08-23-2026 | B20: =IFERROR(__xludf.DUMMYFUNCTION("""COMPUTED_VALUE"""),"randy") -> randy | C20: =IFERROR(__xludf.DUMMYFUNCTION("""COMPUTED_VALUE"""),"Pelanggaran SOP") -> Pelanggaran SOP | D20: =IFERROR(__xludf.DUMMYFUNCTION("""COMPUTED_VALUE"""),"lalai") -> lalai | E20: =IFERROR(__xludf.DUMMYFUNCTION("""COMPUTED_VALUE"""),"Sp1") -> Sp1 | G20: =IFERROR(__xludf.DUMMYFUNCTION("""COMPUTED_VALUE"""),"Wedang uwuh Ngawi") -> Wedang uwuh Ngawi | H20: =IFERROR(__xludf.DUMMYFUNCTION("""COMPUTED_VALUE"""),"Puzzle") -> Puzzle | I20: =IFERROR(__xludf.DUMMYFUNCTION("""COMPUTED_VALUE"""),0.8538461538461538) -> 0.85384615 | K20: =IFERROR(__xludf.DUMMYFUNCTION("QUERY('Analisis Menu Engineering'!A9:I47, ""SELECT A, F, E WHERE I = 'Dog' ORDER BY F ASC, E ASC"", 0)"),"Wi Hel Mina Dream") -> Wi Hel Mina Dream | L20: =IFERROR(__xludf.DUMMYFUNCTION("""COMPUTED_VALUE"""),12.0) -> 12 | M20: =IFERROR(__xludf.DUMMYFUNCTION("""COMPUTED_VALUE"""),0.6516071428571428) -> 0.65160714
G21: =IFERROR(__xludf.DUMMYFUNCTION("""COMPUTED_VALUE"""),"Tier 1 V60") -> Tier 1 V60 | H21: =IFERROR(__xludf.DUMMYFUNCTION("""COMPUTED_VALUE"""),"Puzzle") -> Puzzle | I21: =IFERROR(__xludf.DUMMYFUNCTION("""COMPUTED_VALUE"""),0.7966666666666666) -> 0.79666667 | K21: =IFERROR(__xludf.DUMMYFUNCTION("""COMPUTED_VALUE"""),"Air mineral") -> Air mineral | L21: =IFERROR(__xludf.DUMMYFUNCTION("""COMPUTED_VALUE"""),13.0) -> 13 | M21: =IFERROR(__xludf.DUMMYFUNCTION("""COMPUTED_VALUE"""),0.6875) -> 0.6875
G22: =IFERROR(__xludf.DUMMYFUNCTION("""COMPUTED_VALUE"""),"Espresso") -> Espresso | H22: =IFERROR(__xludf.DUMMYFUNCTION("""COMPUTED_VALUE"""),"Puzzle") -> Puzzle | I22: =IFERROR(__xludf.DUMMYFUNCTION("""COMPUTED_VALUE"""),0.7866666666666666) -> 0.78666667 | K22: =IFERROR(__xludf.DUMMYFUNCTION("""COMPUTED_VALUE"""),"Tier 2 V60") -> Tier 2 V60 | L22: =IFERROR(__xludf.DUMMYFUNCTION("""COMPUTED_VALUE"""),14.0) -> 14 | M22: =IFERROR(__xludf.DUMMYFUNCTION("""COMPUTED_VALUE"""),0.45647058823529413) -> 0.45647059
G23: =IFERROR(__xludf.DUMMYFUNCTION("""COMPUTED_VALUE"""),"Tela goreng") -> Tela goreng | H23: =IFERROR(__xludf.DUMMYFUNCTION("""COMPUTED_VALUE"""),"Puzzle") -> Puzzle | I23: =IFERROR(__xludf.DUMMYFUNCTION("""COMPUTED_VALUE"""),0.779) -> 0.779 | K23: =IFERROR(__xludf.DUMMYFUNCTION("""COMPUTED_VALUE"""),"Pretty Queen") -> Pretty Queen | L23: =IFERROR(__xludf.DUMMYFUNCTION("""COMPUTED_VALUE"""),16.0) -> 16 | M23: =IFERROR(__xludf.DUMMYFUNCTION("""COMPUTED_VALUE"""),0.5416666666666666) -> 0.54166667
G24: =IFERROR(__xludf.DUMMYFUNCTION("""COMPUTED_VALUE"""),"Singkong goreng") -> Singkong goreng | H24: =IFERROR(__xludf.DUMMYFUNCTION("""COMPUTED_VALUE"""),"Puzzle") -> Puzzle | I24: =IFERROR(__xludf.DUMMYFUNCTION("""COMPUTED_VALUE"""),0.779) -> 0.779 | K24: =IFERROR(__xludf.DUMMYFUNCTION("""COMPUTED_VALUE"""),"Cappucino") -> Cappucino | L24: =IFERROR(__xludf.DUMMYFUNCTION("""COMPUTED_VALUE"""),20.0) -> 20 | M24: =IFERROR(__xludf.DUMMYFUNCTION("""COMPUTED_VALUE"""),0.694) -> 0.694
G25: =IFERROR(__xludf.DUMMYFUNCTION("""COMPUTED_VALUE"""),"Cikalopi") -> Cikalopi | H25: =IFERROR(__xludf.DUMMYFUNCTION("""COMPUTED_VALUE"""),"Puzzle") -> Puzzle | I25: =IFERROR(__xludf.DUMMYFUNCTION("""COMPUTED_VALUE"""),0.7777272727272727) -> 0.77772727 | K25: =IFERROR(__xludf.DUMMYFUNCTION("""COMPUTED_VALUE"""),"Hongkong Soft Tale") -> Hongkong Soft Tale | L25: =IFERROR(__xludf.DUMMYFUNCTION("""COMPUTED_VALUE"""),25.0) -> 25 | M25: =IFERROR(__xludf.DUMMYFUNCTION("""COMPUTED_VALUE"""),0.5714285714285714) -> 0.57142857
G26: =IFERROR(__xludf.DUMMYFUNCTION("""COMPUTED_VALUE"""),"Aubergine Crunch") -> Aubergine Crunch | H26: =IFERROR(__xludf.DUMMYFUNCTION("""COMPUTED_VALUE"""),"Puzzle") -> Puzzle | I26: =IFERROR(__xludf.DUMMYFUNCTION("""COMPUTED_VALUE"""),0.7727272727272727) -> 0.77272727 | K26: =IFERROR(__xludf.DUMMYFUNCTION("""COMPUTED_VALUE"""),"Chun Matcha") -> Chun Matcha | L26: =IFERROR(__xludf.DUMMYFUNCTION("""COMPUTED_VALUE"""),30.0) -> 30 | M26: =IFERROR(__xludf.DUMMYFUNCTION("""COMPUTED_VALUE"""),0.6428571428571429) -> 0.64285714
G27: =IFERROR(__xludf.DUMMYFUNCTION("""COMPUTED_VALUE"""),"Red Light District") -> Red Light District | H27: =IFERROR(__xludf.DUMMYFUNCTION("""COMPUTED_VALUE"""),"Puzzle") -> Puzzle | I27: =IFERROR(__xludf.DUMMYFUNCTION("""COMPUTED_VALUE"""),0.7452380952380953) -> 0.7452381 | K27: =IFERROR(__xludf.DUMMYFUNCTION("""COMPUTED_VALUE"""),"Jong Java") -> Jong Java | L27: =IFERROR(__xludf.DUMMYFUNCTION("""COMPUTED_VALUE"""),31.0) -> 31 | M27: =IFERROR(__xludf.DUMMYFUNCTION("""COMPUTED_VALUE"""),0.5119047619047619) -> 0.51190476
K28: =IFERROR(__xludf.DUMMYFUNCTION("""COMPUTED_VALUE"""),"Nastar Frappe") -> Nastar Frappe | L28: =IFERROR(__xludf.DUMMYFUNCTION("""COMPUTED_VALUE"""),34.0) -> 34 | M28: =IFERROR(__xludf.DUMMYFUNCTION("""COMPUTED_VALUE"""),0.716) -> 0.716
K29: =IFERROR(__xludf.DUMMYFUNCTION("""COMPUTED_VALUE"""),"Tier 3 V60") -> Tier 3 V60 | L29: =IFERROR(__xludf.DUMMYFUNCTION("""COMPUTED_VALUE"""),38.0) -> 38 | M29: =IFERROR(__xludf.DUMMYFUNCTION("""COMPUTED_VALUE"""),0.3845454545454545) -> 0.38454545
K30: =IFERROR(__xludf.DUMMYFUNCTION("""COMPUTED_VALUE"""),"Sunny Beach") -> Sunny Beach | L30: =IFERROR(__xludf.DUMMYFUNCTION("""COMPUTED_VALUE"""),41.0) -> 41 | M30: =IFERROR(__xludf.DUMMYFUNCTION("""COMPUTED_VALUE"""),0.716) -> 0.716

Sheet Dashboard
A1: TOTAL OMZET | C1: LABA BERSIH OPERASIONAL | F1: PRIVE SUDAH DIAMBIL | I1: KUOTA PRIVE AMAN (KAS BEBAS)
A2: =Calc_Data!Y1 -> 53797500 | C2: =Calc_Data!Y2 -> 11360945 | F2: =Calc_Data!Y7 -> 11788100 | I2: =Calc_Data!Y2-Calc_Data!Y7 -> -427155
A3: Akumulasi Penjualan Kafe | C3: Laba Murni Sebelum Prive | F3: Total Penarikan Pribadi | I3: Estimasi Kas Bebas Siap Tarik
A6: Indikator Rasio | C6: Rasio Aktual | D6: Target Benchmark | F6: Status Kesehatan | H6: Interpretasi & Rekomendasi
A7: COGS Ratio (Bahan Baku) | C7: =Calc_Data!Y5/Calc_Data!Y1 -> 0.28111446 | D7: 28.0% - 35.0% | F7: =IF(C7<=35%, "AMAN (EFISIEN)", "PERLU EFISIENSI") -> AMAN (EFISIEN) | H7: HPP bahan baku terkendali di bawah batas maksimum 35%
A8: Labor / Gaji Ratio | C8: {=INDEX(Calc_Data!AD:AD, MATCH("Gaji", Calc_Data!AC:AC, 0))/Calc_Data!Y1} -> 0.1376458 | D8: 15.0% - 20.0% | F8: =IF(C8<=20%, "IDEAL (PRODUKTIF)", "TINGGI") -> IDEAL (PRODUKTIF) | H8: Beban gaji karyawan proporsional dan efisien terhadap omzet
A9: Net Profit Margin | C9: =Calc_Data!Y2/Calc_Data!Y1 -> 0.21117979 | D9: 20.0% - 35.0% | F9: =IF(C9>=20%, "SANGAT SEHAT", "DI BAWAH TARGET") -> SANGAT SEHAT | H9: Laba bersih operasional prima, ruang aman untuk prive pemilik
A11: RINGKASAN ARUS KAS & CADANGAN WAJIB (OWNER DRAWING CALCULATOR)
A12: Komponen Arus Kas & Cadangan Wajib | E12: Nominal Alokasi | G12: Klasifikasi | I12: Keterangan & Kebijakan Likuiditas
A13: Estimasi Kas Masuk Bersih (Omzet Kafe) | E13: =Calc_Data!Y1 -> 53797500 | G13: Kas Masuk | I13: Total penerimaan kas operasional dari penjualan kafe
A14: Alokasi Cadangan Belanja Stok Bahan Baku | E14: =Calc_Data!W2 -> 15752572 | G14: Cadangan Wajib | I14: Rekap belanja bahan baku yang dialokasikan untuk perputaran persediaan
A15: Alokasi Cadangan Gaji Karyawan Berikutnya | E15: {=INDEX(Calc_Data!AD:AD, MATCH("Gaji", Calc_Data!AC:AC, 0))} -> 7405000 | G15: Cadangan Wajib | I15: Disisihkan penuh untuk kepastian pembayaran hak karyawan & barista
A16: Penarikan Prive Pemilik (Sudah Ditarik) | E16: =Calc_Data!Y7 -> 11788100 | G16: Penarikan Pribadi | I16: Akumulasi dana yang telah ditarik pemilik pada periode berjalan
A17: Sisa Kas Bersih Pemilik Siap Ditarik | E17: =Calc_Data!Y2-Calc_Data!Y7 -> -427155 | G17: Kas Bebas Aman | I17: Maksimum dana aman ditarik ke rekening pribadi tanpa ganggu operasional
A18: Status Likuiditas & Rekomendasi Penarikan | E18: =IF(E17>0, "AMAN DITARIK", "TUNDA PENARIKAN") -> TUNDA PENARIKAN | G18: Rekomendasi | I18: =IF(E17>0, "Likuiditas mencukupi, disarankan menyisakan saldo buffer 10%", "Operasional ketat, prioritaskan cadangan bahan baku & payroll") -> Operasional ketat, prioritaskan cadangan bahan baku & payroll
L25: =IFERROR(__xludf.DUMMYFUNCTION("QUERY({ARRAYFORMULA(IF(Calc_Data!A2:A1008="""", """", YEAR(Calc_Data!A2:A1008)&""-W""&TEXT(ISOWEEKNUM(Calc_Data!A2:A1008),""00""))), Calc_Data!B2:E1008}, ""Select Col1, sum(Col2), sum(Col4), sum(Col3), sum(Col5) where Col1 is not null and Col1 <> '' group"&" by Col1 label Col1 'Minggu', sum(Col2) 'Total Pendapatan', sum(Col4) 'Total Pengeluaran', sum(Col3) 'Total COGS', sum(Col5) 'Laba Bersih'"")"),"Minggu") -> Minggu | M25: =IFERROR(__xludf.DUMMYFUNCTION("""COMPUTED_VALUE"""),"Total Pendapatan") -> Total Pendapatan | N25: =IFERROR(__xludf.DUMMYFUNCTION("""COMPUTED_VALUE"""),"Total Pengeluaran") -> Total Pengeluaran | O25: =IFERROR(__xludf.DUMMYFUNCTION("""COMPUTED_VALUE"""),"Total COGS") -> Total COGS | P25: =IFERROR(__xludf.DUMMYFUNCTION("""COMPUTED_VALUE"""),"Laba Bersih") -> Laba Bersih
L26: =IFERROR(__xludf.DUMMYFUNCTION("""COMPUTED_VALUE"""),"2026-W33") -> 2026-W33 | M26: =IFERROR(__xludf.DUMMYFUNCTION("""COMPUTED_VALUE"""),1.7662E7) -> 17662000 | N26: =IFERROR(__xludf.DUMMYFUNCTION("""COMPUTED_VALUE"""),4104800.0) -> 4104800 | O26: =IFERROR(__xludf.DUMMYFUNCTION("""COMPUTED_VALUE"""),5209186.0) -> 5209186 | P26: =IFERROR(__xludf.DUMMYFUNCTION("""COMPUTED_VALUE"""),8348014.0) -> 8348014
L27: =IFERROR(__xludf.DUMMYFUNCTION("""COMPUTED_VALUE"""),"2026-W34") -> 2026-W34 | M27: =IFERROR(__xludf.DUMMYFUNCTION("""COMPUTED_VALUE"""),1.3569E7) -> 13569000 | N27: =IFERROR(__xludf.DUMMYFUNCTION("""COMPUTED_VALUE"""),5698500.0) -> 5698500 | O27: =IFERROR(__xludf.DUMMYFUNCTION("""COMPUTED_VALUE"""),2711608.0) -> 2711608 | P27: =IFERROR(__xludf.DUMMYFUNCTION("""COMPUTED_VALUE"""),5158892.0) -> 5158892
L28: =IFERROR(__xludf.DUMMYFUNCTION("""COMPUTED_VALUE"""),"2026-W35") -> 2026-W35 | M28: =IFERROR(__xludf.DUMMYFUNCTION("""COMPUTED_VALUE"""),8689000.0) -> 8689000 | N28: =IFERROR(__xludf.DUMMYFUNCTION("""COMPUTED_VALUE"""),1.0684E7) -> 10684000 | O28: =IFERROR(__xludf.DUMMYFUNCTION("""COMPUTED_VALUE"""),2592797.0) -> 2592797 | P28: =IFERROR(__xludf.DUMMYFUNCTION("""COMPUTED_VALUE"""),-4587797.0) -> -4587797
L29: =IFERROR(__xludf.DUMMYFUNCTION("""COMPUTED_VALUE"""),"2026-W36") -> 2026-W36 | M29: =IFERROR(__xludf.DUMMYFUNCTION("""COMPUTED_VALUE"""),8275000.0) -> 8275000 | N29: =IFERROR(__xludf.DUMMYFUNCTION("""COMPUTED_VALUE"""),1176000.0) -> 1176000 | O29: =IFERROR(__xludf.DUMMYFUNCTION("""COMPUTED_VALUE"""),2715637.0) -> 2715637 | P29: =IFERROR(__xludf.DUMMYFUNCTION("""COMPUTED_VALUE"""),4383363.0) -> 4383363
L30: =IFERROR(__xludf.DUMMYFUNCTION("""COMPUTED_VALUE"""),"2026-W37") -> 2026-W37 | M30: =IFERROR(__xludf.DUMMYFUNCTION("""COMPUTED_VALUE"""),5602500.0) -> 5602500 | N30: =IFERROR(__xludf.DUMMYFUNCTION("""COMPUTED_VALUE"""),5650000.0) -> 5650000 | O30: =IFERROR(__xludf.DUMMYFUNCTION("""COMPUTED_VALUE"""),1894027.0) -> 1894027 | P30: =IFERROR(__xludf.DUMMYFUNCTION("""COMPUTED_VALUE"""),-1941527.0) -> -1941527

Sheet Master Menu
B2: Master Menu & COGS
B4: Nama Menu | C4: Harga Jual | D4: Modal (COGS) | E4: Laba per Porsi | F4: Margin Laba
B5: Sexy Lady | C5: 25000 | D5: 7100 | E5: =C5-D5 -> 17900 | F5: =IFERROR(E5/C5, 0) -> 0.716
B6: Party Plate | C6: 30000 | D6: 15543 | E6: =C6-D6 -> 14457 | F6: =IFERROR(E6/C6, 0) -> 0.4819
B7: Latte Ice | C7: 25000 | D7: 7650 | E7: =C7-D7 -> 17350 | F7: =IFERROR(E7/C7, 0) -> 0.694
B8: Nasi Goreng Kara | C8: 25000 | D8: 7920 | E8: =C8-D8 -> 17080 | F8: =IFERROR(E8/C8, 0) -> 0.6832
B9: Mie Yabi | C9: 25000 | D9: 7380 | E9: =C9-D9 -> 17620 | F9: =IFERROR(E9/C9, 0) -> 0.7048
B10: Sour tea | C10: 19000 | D10: 3659 | E10: =C10-D10 -> 15341 | F10: =IFERROR(E10/C10, 0) -> 0.80742105
B11: americano | C11: 18000 | D11: 5200 | E11: =C11-D11 -> 12800 | F11: =IFERROR(E11/C11, 0) -> 0.71111111
B12: Latte | C12: 25000 | D12: 7650 | E12: =C12-D12 -> 17350 | F12: =IFERROR(E12/C12, 0) -> 0.694
B13: Nastar Frappe | C13: 25000 | D13: 7100 | E13: =C13-D13 -> 17900 | F13: =IFERROR(E13/C13, 0) -> 0.716
B14: Teh puncak Jamus | C14: 15000 | D14: 270 | E14: =C14-D14 -> 14730 | F14: =IFERROR(E14/C14, 0) -> 0.982
B15: Air mineral besar | C15: 17500 | D15: 3300 | E15: =C15-D15 -> 14200 | F15: =IFERROR(E15/C15, 0) -> 0.81142857
B16: Teh Belanda | C16: 13500 | D16: 350 | E16: =C16-D16 -> 13150 | F16: =IFERROR(E16/C16, 0) -> 0.97407407
... B32: Espresso | C32: 15000 | D32: 3200 | E32: =C32-D32 -> 11800 | F32: =IFERROR(E32/C32, 0) -> 0.78666667
B33: Chun Matcha | C33: 35000 | D33: 12500 | E33: =IF(B33="","", C33-D33) -> 22500 | F33: =IF(B33="","", IF(C33=0, 0, E33/C33)) -> 0.64285714
B34: Natie Matcha | C34: 38000 | D34: 15000 | E34: =IF(B34="","", C34-D34) -> 23000 | F34: =IF(B34="","", IF(C34=0, 0, E34/C34)) -> 0.60526316
B35: Pure Chocolade | C35: 29000 | D35: 5200 | E35: =IF(B35="","", C35-D35) -> 23800 | F35: =IF(B35="","", IF(C35=0, 0, E35/C35)) -> 0.82068966
B36: Claudio (Vanilla) | C36: 26000 | D36: 2800 | E36: =IF(B36="","", C36-D36) -> 23200 | F36: =IF(B36="","", IF(C36=0, 0, E36/C36)) -> 0.89230769
B37: Ivada (Stroberi) | C37: 26000 | D37: 2800 | E37: =IF(B37="","", C37-D37) -> 23200 | F37: =IF(B37="","", IF(C37=0, 0, E37/C37)) -> 0.89230769
B38: Vicenzo (Coklat) | C38: 26000 | D38: 2800 | E38: =IF(B38="","", C38-D38) -> 23200 | F38: =IF(B38="","", IF(C38=0, 0, E38/C38)) -> 0.89230769
B39: Capri ijz (Campur) | C39: 26000 | D39: 2800 | E39: =IF(B39="","", C39-D39) -> 23200 | F39: =IF(B39="","", IF(C39=0, 0, E39/C39)) -> 0.89230769
B40: Sweety hazy | C40: 29000 | D40: 4790 | E40: =IF(B40="","", C40-D40) -> 24210 | F40: =IF(B40="","", IF(C40=0, 0, E40/C40)) -> 0.83482759
B41: Cikalopi | C41: 33000 | D41: 7335 | E41: =IF(B41="","", C41-D41) -> 25665 | F41: =IF(B41="","", IF(C41=0, 0, E41/C41)) -> 0.77772727
B42: Cappucino | C42: 25000 | D42: 7650 | E42: =IF(B42="","", C42-D42) -> 17350 | F42: =IF(B42="","", IF(C42=0, 0, E42/C42)) -> 0.694
B43: Aubergine Crunch | C43: 22000 | D43: 5000 | E43: =IF(B43="","", C43-D43) -> 17000 | F43: =IF(B43="","", IF(C43=0, 0, E43/C43)) -> 0.77272727
B44: Special Barista | C44: 99000 | D44: 54160 | E44: =IF(B44="","", C44-D44) -> 44840 | F44: =IF(B44="","", IF(C44=0, 0, E44/C44)) -> 0.45292929
... B46: Kopi Kakek | C46: 10000 | D46: 2700 | E46: =IF(B46="","", C46-D46) -> 7300 | F46: =IF(B46="","", IF(C46=0, 0, E46/C46)) -> 0.73
E47: =IF(B47="","", C47-D47) | F47: =IF(B47="","", IF(C47=0, 0, E47/C47))
E48: =IF(B48="","", C48-D48) | F48: =IF(B48="","", IF(C48=0, 0, E48/C48))
E49: =IF(B49="","", C49-D49) | F49: =IF(B49="","", IF(C49=0, 0, E49/C49))
E50: =IF(B50="","", C50-D50) | F50: =IF(B50="","", IF(C50=0, 0, E50/C50))

Sheet Log Pengeluaran
B2: Log Pengeluaran (Uang Keluar)
G3: Pilih Kategori | H3: Total Pengeluaran
B4: Tanggal | C4: Kategori | D4: Keterangan | E4: Nominal | F4: Bukti Nota | G4: Gaji | H4: =IF(G4="", SUM(E5:E3000), SUMIF(C5:C3000, G4, E5:E3000)) -> 4860000
B5: 46272 | C5: Gaji | D5: Gala, Randy, Adi, Anto | E5: 3400000
B6: 46272 | C6: Gaji | D6: Habib | E6: 400000 | G6: Tanggal | H6: Kategori | I6: Keterangan | J6: Nominal | K6: Bukti Nota
B7: 46266 | C7: Bahan Baku | D7: selada | E7: 5000 | G7: =IFERROR(__xludf.DUMMYFUNCTION("IFNA(FILTER(B5:F3000, C5:C3000=G4), ""Tidak ada data"")"),46272.0) -> 46272 | H7: =IFERROR(__xludf.DUMMYFUNCTION("""COMPUTED_VALUE"""),"Gaji") -> Gaji | I7: =IFERROR(__xludf.DUMMYFUNCTION("""COMPUTED_VALUE"""),"Gala, Randy, Adi, Anto") -> Gala, Randy, Adi, Anto | J7: =IFERROR(__xludf.DUMMYFUNCTION("""COMPUTED_VALUE"""),3400000.0) -> 3400000
B8: 46266 | C8: Operasional | D8: cup | E8: 39000 | G8: =IFERROR(__xludf.DUMMYFUNCTION("""COMPUTED_VALUE"""),46272.0) -> 46272 | H8: =IFERROR(__xludf.DUMMYFUNCTION("""COMPUTED_VALUE"""),"Gaji") -> Gaji | I8: =IFERROR(__xludf.DUMMYFUNCTION("""COMPUTED_VALUE"""),"Habib") -> Habib | J8: =IFERROR(__xludf.DUMMYFUNCTION("""COMPUTED_VALUE"""),400000.0) -> 400000
B9: 46266 | C9: Bahan Baku | D9: susu diamond | E9: 41000 | G9: =IFERROR(__xludf.DUMMYFUNCTION("""COMPUTED_VALUE"""),46273.0) -> 46273 | H9: =IFERROR(__xludf.DUMMYFUNCTION("""COMPUTED_VALUE"""),"Gaji") -> Gaji | I9: =IFERROR(__xludf.DUMMYFUNCTION("""COMPUTED_VALUE"""),"Mas riyan") -> Mas riyan | J9: =IFERROR(__xludf.DUMMYFUNCTION("""COMPUTED_VALUE"""),1060000.0) -> 1060000
B10: 46266 | C10: Bahan Baku | D10: ketang crinkle | E10: 60000
B11: 46266 | C11: Bahan Baku | D11: Ayam karage | E11: 89000
B12: 46266 | C12: Bahan Baku | D12: kopi tier 1,2,3 | E12: 553000
B13: 46266 | C13: Operasional | D13: token listrik | E13: 100000
B14: 46267 | C14: Operasional | D14: token listrik | E14: 102000
B15: 46267 | C15: Lain-lain | D15: skop ice cream | E15: 96000
B16: 46267 | C16: Bahan Baku | D16: Marjan strobery | E16: 20500
B17: 46267 | C17: Bahan Baku | D17: selai strobery | E17: 10500
B18: 46267 | C18: Lain-lain | D18: bayar tukang | E18: 200000
B19: 46267 | C19: Bahan Baku | D19: susu diamond | E19: 41000
B20: 46268 | C20: prive | D20: kasbon | E20: 600000
B21: 46268 | C21: Pemasaran | D21: marketing | E21: 110000
... B90: 46274 | C90: Bahan Baku | D90: bubuk coklat | E90: 250000
C91: Bahan Baku

Sheet Buku Kasir
A1: Total Pendapatan | C1: 9455000 | D1: 0 | E1: 1023500 | F1: 2426000 | G1: 2867500 | H1: 1237500 | I1: 909000 | J1: 1389000 | K1: 367000 | L1: 1289000 | M1: 2079500 | N1: 993000 | O1: 826000 | P1: 1076000 | Q1: 691000 | R1: 1104000 | S1: 1557000 | T1: 2202500 | U1: 1232500 | V1: 1457500 | W1: 984500 | X1: {=SUM(IFERROR($B7:$B1002 * X7:X1002, 0))} -> 1052000 | Y1: {=SUM(IFERROR($B7:$B1002 * Y7:Y1002, 0))} -> 775000 | Z1: {=SUM(IFERROR($B7:$B1002 * Z7:Z1002, 0))} -> 1001500 | AA1: {=SUM(IFERROR($B7:$B1002 * AA7:AA1002, 0))} -> 1140500 | AB1: {=SUM(IFERROR($B7:$B1002 * AB7:AB1002, 0))} -> 1864000 | AC1: {=SUM(IFERROR($B7:$B1002 * AC7:AC1002, 0))} -> 2828000 | AD1: {=SUM(IFERROR($B7:$B1002 * AD7:AD1002, 0))} -> 1735500 | AE1: {=SUM(IFERROR($B7:$B1002 * AE7:AE1002, 0))} -> 1039000 | ... AG1: {=SUM(IFERROR($B7:$B1002 * AG7:AG1002, 0))} -> 0
A2: Total Kotor | C2: 3165595 | D2: 0 | E2: 256481 | F2: 848281 | G2: 938829 | H2: 382947 | I2: 298501 | J2: 424826 | K2: 112297 | L2: 471553 | M2: 617263 | N2: 404221 | O2: 200176 | P2: 344849 | Q2: 173735 | R2: 367764 | S2: 410112 | T2: 665516 | U2: 430645 | V2: 507915 | W2: 366254 | X2: {=SUM(IFERROR(X7:X1002 * VLOOKUP($A7:$A1002, 'Master Menu'!$B$5:$D1002, 3, FALSE), 0))} -> 313440 | Y2: {=SUM(IFERROR(Y7:Y1002 * VLOOKUP($A7:$A1002, 'Master Menu'!$B$5:$D1002, 3, FALSE), 0))} -> 216969 | Z2: {=SUM(IFERROR(Z7:Z1002 * VLOOKUP($A7:$A1002, 'Master Menu'!$B$5:$D1002, 3, FALSE), 0))} -> 325299 | AA2: {=SUM(IFERROR(AA7:AA1002 * VLOOKUP($A7:$A1002, 'Master Menu'!$B$5:$D1002, 3, FALSE), 0))} -> 360417 | AB2: {=SUM(IFERROR(AB7:AB1002 * VLOOKUP($A7:$A1002, 'Master Menu'!$B$5:$D1002, 3, FALSE), 0))} -> 625343 | AC2: {=SUM(IFERROR(AC7:AC1002 * VLOOKUP($A7:$A1002, 'Master Menu'!$B$5:$D1002, 3, FALSE), 0))} -> 927211 | AD2: {=SUM(IFERROR(AD7:AD1002 * VLOOKUP($A7:$A1002, 'Master Menu'!$B$5:$D1002, 3, FALSE), 0))} -> 665052 | AE2: {=SUM(IFERROR(AE7:AE1002 * VLOOKUP($A7:$A1002, 'Master Menu'!$B$5:$D1002, 3, FALSE), 0))} -> 301764 | ... AG2: {=SUM(IFERROR(AG7:AG1002 * VLOOKUP($A7:$A1002, 'Master Menu'!$B$5:$D1002, 3, FALSE), 0))} -> 0
A3: Pendapatan Bersih | C3: {=IF(C5:AG5<>"", C1:AG1 - C2:AG2, "")} -> 6289405 | D3: 0 | E3: 767019 | F3: 1577719 | G3: 1928671 | H3: 854553 | I3: 610499 | J3: 964174 | K3: 254703 | L3: 817447 | M3: 1462237 | N3: 588779 | O3: 625824 | P3: 731151 | Q3: 517265 | R3: 736236 | S3: 1146888 | T3: 1536984 | U3: 801855 | V3: 949585 | W3: 618246 | X3: 738560 | Y3: 558031 | Z3: 676201 | AA3: 780083 | AB3: 1238657 | AC3: 1900789 | AD3: 1070448 | AE3: 737236 | AF3: 0 | AG3: 0
C4: 7-13 rekap
A5: Nama Menu | B5: Harga Jual | C5: 46246 | D5: =C5+1 -> 46247 | E5: =D5+1 -> 46248 | F5: =E5+1 -> 46249 | G5: =F5+1 -> 46250 | H5: =G5+1 -> 46251 | I5: =H5+1 -> 46252 | J5: =I5+1 -> 46253 | K5: =J5+1 -> 46254 | ... AG5: =AF5+1 -> 46276
A6: ='Master Menu'!B4 -> Nama Menu | B6: ='Master Menu'!C4 -> Harga Jual
A7: =IFERROR(__xludf.DUMMYFUNCTION("FILTER('Master Menu'!B5:C1002, 'Master Menu'!B5:B1002<>"""")"),"Sexy Lady") -> Sexy Lady | B7: =IFERROR(__xludf.DUMMYFUNCTION("""COMPUTED_VALUE"""),25000.0) -> 25000 | C7: 71 | D7: 0 | E7: 4 | F7: 6 | G7: 4 | H7: 7 | I7: 4 | J7: 2 | K7: 0 | L7: 4 | M7: 8 | N7: 1 | O7: 2 | P7: 0 | Q7: 1 | R7: 2 | S7: 1 | T7: 18 | U7: 3 | V7: 0 | W7: 1 | X7: =SUMIFS('Drop Data Kasir'!$B:$B, 'Drop Data Kasir'!$A:$A, $A7, 'Drop Data Kasir'!$C:$C, X$5) -> 7 | Y7: =SUMIFS('Drop Data Kasir'!$B:$B, 'Drop Data Kasir'!$A:$A, $A7, 'Drop Data Kasir'!$C:$C, Y$5) -> 4 | Z7: =SUMIFS('Drop Data Kasir'!$B:$B, 'Drop Data Kasir'!$A:$A, $A7, 'Drop Data Kasir'!$C:$C, Z$5) -> 10 | AA7: =SUMIFS('Drop Data Kasir'!$B:$B, 'Drop Data Kasir'!$A:$A, $A7, 'Drop Data Kasir'!$C:$C, AA$5) -> 0 | AB7: =SUMIFS('Drop Data Kasir'!$B:$B, 'Drop Data Kasir'!$A:$A, $A7, 'Drop Data Kasir'!$C:$C, AB$5) -> 6 | AC7: =SUMIFS('Drop Data Kasir'!$B:$B, 'Drop Data Kasir'!$A:$A, $A7, 'Drop Data Kasir'!$C:$C, AC$5) -> 12 | AD7: =SUMIFS('Drop Data Kasir'!$B:$B, 'Drop Data Kasir'!$A:$A, $A7, 'Drop Data Kasir'!$C:$C, AD$5) -> 2 | AE7: =SUMIFS('Drop Data Kasir'!$B:$B, 'Drop Data Kasir'!$A:$A, $A7, 'Drop Data Kasir'!$C:$C, AE$5) -> 3 | ... AG7: =SUMIFS('Drop Data Kasir'!$B:$B, 'Drop Data Kasir'!$A:$A, $A7, 'Drop Data Kasir'!$C:$C, AG$5) -> 0
A8: =IFERROR(__xludf.DUMMYFUNCTION("""COMPUTED_VALUE"""),"Party Plate") -> Party Plate | B8: =IFERROR(__xludf.DUMMYFUNCTION("""COMPUTED_VALUE"""),30000.0) -> 30000 | C8: 35 | D8: 0 | E8: 0 | F8: 12 | G8: 8 | H8: 2 | I8: 5 | J8: 2 | K8: 0 | L8: 6 | M8: 5 | N8: 3 | O8: 1 | P8: 2 | Q8: 1 | R8: 4 | S8: 2 | T8: 4 | U8: 4 | V8: 4 | W8: 5 | X8: =SUMIFS('Drop Data Kasir'!$B:$B, 'Drop Data Kasir'!$A:$A, $A8, 'Drop Data Kasir'!$C:$C, X$5) -> 1 | Y8: =SUMIFS('Drop Data Kasir'!$B:$B, 'Drop Data Kasir'!$A:$A, $A8, 'Drop Data Kasir'!$C:$C, Y$5) -> 2 | Z8: =SUMIFS('Drop Data Kasir'!$B:$B, 'Drop Data Kasir'!$A:$A, $A8, 'Drop Data Kasir'!$C:$C, Z$5) -> 1 | AA8: =SUMIFS('Drop Data Kasir'!$B:$B, 'Drop Data Kasir'!$A:$A, $A8, 'Drop Data Kasir'!$C:$C, AA$5) -> 0 | AB8: =SUMIFS('Drop Data Kasir'!$B:$B, 'Drop Data Kasir'!$A:$A, $A8, 'Drop Data Kasir'!$C:$C, AB$5) -> 3 | AC8: =SUMIFS('Drop Data Kasir'!$B:$B, 'Drop Data Kasir'!$A:$A, $A8, 'Drop Data Kasir'!$C:$C, AC$5) -> 5 | AD8: =SUMIFS('Drop Data Kasir'!$B:$B, 'Drop Data Kasir'!$A:$A, $A8, 'Drop Data Kasir'!$C:$C, AD$5) -> 3 | AE8: =SUMIFS('Drop Data Kasir'!$B:$B, 'Drop Data Kasir'!$A:$A, $A8, 'Drop Data Kasir'!$C:$C, AE$5) -> 2 | ... AG8: =SUMIFS('Drop Data Kasir'!$B:$B, 'Drop Data Kasir'!$A:$A, $A8, 'Drop Data Kasir'!$C:$C, AG$5) -> 0
A9: =IFERROR(__xludf.DUMMYFUNCTION("""COMPUTED_VALUE"""),"Latte Ice") -> Latte Ice | B9: =IFERROR(__xludf.DUMMYFUNCTION("""COMPUTED_VALUE"""),25000.0) -> 25000 | C9: 32 | D9: 0 | E9: 2 | F9: 15 | G9: 11 | H9: 0 | I9: 2 | J9: 7 | K9: 6 | L9: 6 | M9: 0 | N9: 4 | O9: 1 | P9: 0 | Q9: 5 | R9: 3 | S9: 4 | T9: 8 | U9: 7 | V9: 4 | W9: 4 | X9: =SUMIFS('Drop Data Kasir'!$B:$B, 'Drop Data Kasir'!$A:$A, $A9, 'Drop Data Kasir'!$C:$C, X$5) -> 2 | Y9: =SUMIFS('Drop Data Kasir'!$B:$B, 'Drop Data Kasir'!$A:$A, $A9, 'Drop Data Kasir'!$C:$C, Y$5) -> 1 | Z9: =SUMIFS('Drop Data Kasir'!$B:$B, 'Drop Data Kasir'!$A:$A, $A9, 'Drop Data Kasir'!$C:$C, Z$5) -> 2 | AA9: =SUMIFS('Drop Data Kasir'!$B:$B, 'Drop Data Kasir'!$A:$A, $A9, 'Drop Data Kasir'!$C:$C, AA$5) -> 2 | AB9: =SUMIFS('Drop Data Kasir'!$B:$B, 'Drop Data Kasir'!$A:$A, $A9, 'Drop Data Kasir'!$C:$C, AB$5) -> 2 | AC9: =SUMIFS('Drop Data Kasir'!$B:$B, 'Drop Data Kasir'!$A:$A, $A9, 'Drop Data Kasir'!$C:$C, AC$5) -> 3 | AD9: =SUMIFS('Drop Data Kasir'!$B:$B, 'Drop Data Kasir'!$A:$A, $A9, 'Drop Data Kasir'!$C:$C, AD$5) -> 2 | AE9: =SUMIFS('Drop Data Kasir'!$B:$B, 'Drop Data Kasir'!$A:$A, $A9, 'Drop Data Kasir'!$C:$C, AE$5) -> 2 | ... AG9: =SUMIFS('Drop Data Kasir'!$B:$B, 'Drop Data Kasir'!$A:$A, $A9, 'Drop Data Kasir'!$C:$C, AG$5) -> 0
A10: =IFERROR(__xludf.DUMMYFUNCTION("""COMPUTED_VALUE"""),"Nasi Goreng Kara") -> Nasi Goreng Kara | B10: =IFERROR(__xludf.DUMMYFUNCTION("""COMPUTED_VALUE"""),25000.0) -> 25000 | C10: 31 | D10: 0 | E10: 3 | F10: 9 | G10: 11 | H10: 3 | I10: 1 | J10: 4 | K10: 1 | L10: 5 | M10: 5 | N10: 4 | O10: 2 | P10: 1 | Q10: 0 | R10: 1 | S10: 2 | T10: 5 | U10: 1 | V10: 7 | W10: 0 | X10: =SUMIFS('Drop Data Kasir'!$B:$B, 'Drop Data Kasir'!$A:$A, $A10, 'Drop Data Kasir'!$C:$C, X$5) -> 3 | Y10: =SUMIFS('Drop Data Kasir'!$B:$B, 'Drop Data Kasir'!$A:$A, $A10, 'Drop Data Kasir'!$C:$C, Y$5) -> 3 | Z10: =SUMIFS('Drop Data Kasir'!$B:$B, 'Drop Data Kasir'!$A:$A, $A10, 'Drop Data Kasir'!$C:$C, Z$5) -> 6 | AA10: =SUMIFS('Drop Data Kasir'!$B:$B, 'Drop Data Kasir'!$A:$A, $A10, 'Drop Data Kasir'!$C:$C, AA$5) -> 2 | AB10: =SUMIFS('Drop Data Kasir'!$B:$B, 'Drop Data Kasir'!$A:$A, $A10, 'Drop Data Kasir'!$C:$C, AB$5) -> 12 | AC10: =SUMIFS('Drop Data Kasir'!$B:$B, 'Drop Data Kasir'!$A:$A, $A10, 'Drop Data Kasir'!$C:$C, AC$5) -> 13 | AD10: =SUMIFS('Drop Data Kasir'!$B:$B, 'Drop Data Kasir'!$A:$A, $A10, 'Drop Data Kasir'!$C:$C, AD$5) -> 6 | AE10: =SUMIFS('Drop Data Kasir'!$B:$B, 'Drop Data Kasir'!$A:$A, $A10, 'Drop Data Kasir'!$C:$C, AE$5) -> 5 | ... AG10: =SUMIFS('Drop Data Kasir'!$B:$B, 'Drop Data Kasir'!$A:$A, $A10, 'Drop Data Kasir'!$C:$C, AG$5) -> 0
A11: =IFERROR(__xludf.DUMMYFUNCTION("""COMPUTED_VALUE"""),"Mie Yabi") -> Mie Yabi | B11: =IFERROR(__xludf.DUMMYFUNCTION("""COMPUTED_VALUE"""),25000.0) -> 25000 | C11: 24 | D11: 0 | E11: 0 | F11: 3 | G11: 3 | H11: 2 | I11: 1 | J11: 4 | K11: 0 | L11: 4 | M11: 3 | N11: 2 | O11: 1 | P11: 0 | Q11: 0 | R11: 2 | S11: 1 | T11: 3 | U11: 3 | V11: 2 | W11: 0 | X11: =SUMIFS('Drop Data Kasir'!$B:$B, 'Drop Data Kasir'!$A:$A, $A11, 'Drop Data Kasir'!$C:$C, X$5) -> 1 | Y11: =SUMIFS('Drop Data Kasir'!$B:$B, 'Drop Data Kasir'!$A:$A, $A11, 'Drop Data Kasir'!$C:$C, Y$5) -> 1 | Z11: =SUMIFS('Drop Data Kasir'!$B:$B, 'Drop Data Kasir'!$A:$A, $A11, 'Drop Data Kasir'!$C:$C, Z$5) -> 2 | AA11: =SUMIFS('Drop Data Kasir'!$B:$B, 'Drop Data Kasir'!$A:$A, $A11, 'Drop Data Kasir'!$C:$C, AA$5) -> 0 | AB11: =SUMIFS('Drop Data Kasir'!$B:$B, 'Drop Data Kasir'!$A:$A, $A11, 'Drop Data Kasir'!$C:$C, AB$5) -> 3 | AC11: =SUMIFS('Drop Data Kasir'!$B:$B, 'Drop Data Kasir'!$A:$A, $A11, 'Drop Data Kasir'!$C:$C, AC$5) -> 4 | AD11: =SUMIFS('Drop Data Kasir'!$B:$B, 'Drop Data Kasir'!$A:$A, $A11, 'Drop Data Kasir'!$C:$C, AD$5) -> 2 | AE11: =SUMIFS('Drop Data Kasir'!$B:$B, 'Drop Data Kasir'!$A:$A, $A11, 'Drop Data Kasir'!$C:$C, AE$5) -> 2 | ... AG11: =SUMIFS('Drop Data Kasir'!$B:$B, 'Drop Data Kasir'!$A:$A, $A11, 'Drop Data Kasir'!$C:$C, AG$5) -> 0
A12: =IFERROR(__xludf.DUMMYFUNCTION("""COMPUTED_VALUE"""),"Sour tea") -> Sour tea | B12: =IFERROR(__xludf.DUMMYFUNCTION("""COMPUTED_VALUE"""),19000.0) -> 19000 | C12: 21 | D12: 0 | E12: 1 | F12: 4 | G12: 5 | H12: 3 | I12: 1 | J12: 0 | K12: 3 | L12: 1 | M12: 7 | N12: 1 | O12: 0 | P12: 2 | Q12: 1 | R12: 0 | S12: 1 | T12: 0 | U12: 1 | V12: 2 | W12: 1 | X12: =SUMIFS('Drop Data Kasir'!$B:$B, 'Drop Data Kasir'!$A:$A, $A12, 'Drop Data Kasir'!$C:$C, X$5) -> 3 | Y12: =SUMIFS('Drop Data Kasir'!$B:$B, 'Drop Data Kasir'!$A:$A, $A12, 'Drop Data Kasir'!$C:$C, Y$5) -> 0 | Z12: =SUMIFS('Drop Data Kasir'!$B:$B, 'Drop Data Kasir'!$A:$A, $A12, 'Drop Data Kasir'!$C:$C, Z$5) -> 0 | AA12: =SUMIFS('Drop Data Kasir'!$B:$B, 'Drop Data Kasir'!$A:$A, $A12, 'Drop Data Kasir'!$C:$C, AA$5) -> 1 | AB12: =SUMIFS('Drop Data Kasir'!$B:$B, 'Drop Data Kasir'!$A:$A, $A12, 'Drop Data Kasir'!$C:$C, AB$5) -> 1 | AC12: =SUMIFS('Drop Data Kasir'!$B:$B, 'Drop Data Kasir'!$A:$A, $A12, 'Drop Data Kasir'!$C:$C, AC$5) -> 2 | AD12: =SUMIFS('Drop Data Kasir'!$B:$B, 'Drop Data Kasir'!$A:$A, $A12, 'Drop Data Kasir'!$C:$C, AD$5) -> 1 | AE12: =SUMIFS('Drop Data Kasir'!$B:$B, 'Drop Data Kasir'!$A:$A, $A12, 'Drop Data Kasir'!$C:$C, AE$5) -> 0 | ... AG12: =SUMIFS('Drop Data Kasir'!$B:$B, 'Drop Data Kasir'!$A:$A, $A12, 'Drop Data Kasir'!$C:$C, AG$5) -> 0
A13: =IFERROR(__xludf.DUMMYFUNCTION("""COMPUTED_VALUE"""),"americano") -> americano | B13: =IFERROR(__xludf.DUMMYFUNCTION("""COMPUTED_VALUE"""),18000.0) -> 18000 | C13: 19 | D13: 0 | E13: 5 | F13: 5 | G13: 3 | H13: 2 | I13: 2 | J13: 10 | K13: 2 | L13: 1 | M13: 6 | N13: 0 | O13: 2 | P13: 3 | Q13: 2 | R13: 3 | S13: 4 | T13: 3 | U13: 2 | V13: 1 | W13: 3 | X13: =SUMIFS('Drop Data Kasir'!$B:$B, 'Drop Data Kasir'!$A:$A, $A13, 'Drop Data Kasir'!$C:$C, X$5) -> 1 | Y13: =SUMIFS('Drop Data Kasir'!$B:$B, 'Drop Data Kasir'!$A:$A, $A13, 'Drop Data Kasir'!$C:$C, Y$5) -> 1 | Z13: =SUMIFS('Drop Data Kasir'!$B:$B, 'Drop Data Kasir'!$A:$A, $A13, 'Drop Data Kasir'!$C:$C, Z$5) -> 3 | AA13: =SUMIFS('Drop Data Kasir'!$B:$B, 'Drop Data Kasir'!$A:$A, $A13, 'Drop Data Kasir'!$C:$C, AA$5) -> 2 | AB13: =SUMIFS('Drop Data Kasir'!$B:$B, 'Drop Data Kasir'!$A:$A, $A13, 'Drop Data Kasir'!$C:$C, AB$5) -> 2 | AC13: =SUMIFS('Drop Data Kasir'!$B:$B, 'Drop Data Kasir'!$A:$A, $A13, 'Drop Data Kasir'!$C:$C, AC$5) -> 3 | AD13: =SUMIFS('Drop Data Kasir'!$B:$B, 'Drop Data Kasir'!$A:$A, $A13, 'Drop Data Kasir'!$C:$C, AD$5) -> 0 | AE13: =SUMIFS('Drop Data Kasir'!$B:$B, 'Drop Data Kasir'!$A:$A, $A13, 'Drop Data Kasir'!$C:$C, AE$5) -> 1 | ... AG13: =SUMIFS('Drop Data Kasir'!$B:$B, 'Drop Data Kasir'!$A:$A, $A13, 'Drop Data Kasir'!$C:$C, AG$5) -> 0
A14: =IFERROR(__xludf.DUMMYFUNCTION("""COMPUTED_VALUE"""),"Latte") -> Latte | B14: =IFERROR(__xludf.DUMMYFUNCTION("""COMPUTED_VALUE"""),25000.0) -> 25000 | C14: 18 | D14: 0 | E14: 0 | F14: 0 | G14: 2 | H14: 0 | I14: 0 | J14: 3 | K14: 0 | L14: 0 | M14: 1 | N14: 2 | O14: 2 | P14: 9 | Q14: 0 | R14: 2 | S14: 3 | T14: 10 | U14: 2 | V14: 1 | W14: 1 | X14: =SUMIFS('Drop Data Kasir'!$B:$B, 'Drop Data Kasir'!$A:$A, $A14, 'Drop Data Kasir'!$C:$C, X$5) -> 0 | Y14: =SUMIFS('Drop Data Kasir'!$B:$B, 'Drop Data Kasir'!$A:$A, $A14, 'Drop Data Kasir'!$C:$C, Y$5) -> 0 | Z14: =SUMIFS('Drop Data Kasir'!$B:$B, 'Drop Data Kasir'!$A:$A, $A14, 'Drop Data Kasir'!$C:$C, Z$5) -> 0 | AA14: =SUMIFS('Drop Data Kasir'!$B:$B, 'Drop Data Kasir'!$A:$A, $A14, 'Drop Data Kasir'!$C:$C, AA$5) -> 2 | AB14: =SUMIFS('Drop Data Kasir'!$B:$B, 'Drop Data Kasir'!$A:$A, $A14, 'Drop Data Kasir'!$C:$C, AB$5) -> 2 | AC14: =SUMIFS('Drop Data Kasir'!$B:$B, 'Drop Data Kasir'!$A:$A, $A14, 'Drop Data Kasir'!$C:$C, AC$5) -> 3 | AD14: =SUMIFS('Drop Data Kasir'!$B:$B, 'Drop Data Kasir'!$A:$A, $A14, 'Drop Data Kasir'!$C:$C, AD$5) -> 0 | AE14: =SUMIFS('Drop Data Kasir'!$B:$B, 'Drop Data Kasir'!$A:$A, $A14, 'Drop Data Kasir'!$C:$C, AE$5) -> 1 | AG14: =SUMIFS('Drop Data Kasir'!$B:$B, 'Drop Data Kasir'!$A:$A, $A14, 'Drop Data Kasir'!$C:$C, AG$5) -> 0
A15: =IFERROR(__xludf.DUMMYFUNCTION("""COMPUTED_VALUE"""),"Nastar Frappe") -> Nastar Frappe | B15: =IFERROR(__xludf.DUMMYFUNCTION("""COMPUTED_VALUE"""),25000.0) -> 25000 | C15: 15 | D15: 0 | E15: 2 | F15: 2 | G15: 3 | H15: 1 | I15: 0 | J15: 1 | K15: 0 | L15: 0 | M15: 1 | N15: 0 | O15: 0 | P15: 1 | Q15: 0 | R15: 1 | S15: 0 | T15: 2 | U15: 0 | V15: 0 | W15: 0 | X15: =SUMIFS('Drop Data Kasir'!$B:$B, 'Drop Data Kasir'!$A:$A, $A15, 'Drop Data Kasir'!$C:$C, X$5) -> 0 | Y15: =SUMIFS('Drop Data Kasir'!$B:$B, 'Drop Data Kasir'!$A:$A, $A15, 'Drop Data Kasir'!$C:$C, Y$5) -> 1 | Z15: =SUMIFS('Drop Data Kasir'!$B:$B, 'Drop Data Kasir'!$A:$A, $A15, 'Drop Data Kasir'!$C:$C, Z$5) -> 0 | AA15: =SUMIFS('Drop Data Kasir'!$B:$B, 'Drop Data Kasir'!$A:$A, $A15, 'Drop Data Kasir'!$C:$C, AA$5) -> 0 | AB15: =SUMIFS('Drop Data Kasir'!$B:$B, 'Drop Data Kasir'!$A:$A, $A15, 'Drop Data Kasir'!$C:$C, AB$5) -> 2 | AC15: =SUMIFS('Drop Data Kasir'!$B:$B, 'Drop Data Kasir'!$A:$A, $A15, 'Drop Data Kasir'!$C:$C, AC$5) -> 0 | AD15: =SUMIFS('Drop Data Kasir'!$B:$B, 'Drop Data Kasir'!$A:$A, $A15, 'Drop Data Kasir'!$C:$C, AD$5) -> 1 | AE15: =SUMIFS('Drop Data Kasir'!$B:$B, 'Drop Data Kasir'!$A:$A, $A15, 'Drop Data Kasir'!$C:$C, AE$5) -> 1 | ... AG15: =SUMIFS('Drop Data Kasir'!$B:$B, 'Drop Data Kasir'!$A:$A, $A15, 'Drop Data Kasir'!$C:$C, AG$5) -> 0
A16: =IFERROR(__xludf.DUMMYFUNCTION("""COMPUTED_VALUE"""),"Teh puncak Jamus") -> Teh puncak Jamus | B16: =IFERROR(__xludf.DUMMYFUNCTION("""COMPUTED_VALUE"""),15000.0) -> 15000 | C16: 15 | D16: 0 | E16: 0 | F16: 1 | G16: 0 | H16: 1 | I16: 1 | J16: 5 | K16: 1 | L16: 1 | M16: 6 | N16: 0 | O16: 0 | P16: 3 | Q16: 3 | R16: 0 | S16: 4 | T16: 3 | U16: 0 | V16: 0 | W16: 0 | X16: =SUMIFS('Drop Data Kasir'!$B:$B, 'Drop Data Kasir'!$A:$A, $A16, 'Drop Data Kasir'!$C:$C, X$5) -> 2 | Y16: =SUMIFS('Drop Data Kasir'!$B:$B, 'Drop Data Kasir'!$A:$A, $A16, 'Drop Data Kasir'!$C:$C, Y$5) -> 0 | Z16: =SUMIFS('Drop Data Kasir'!$B:$B, 'Drop Data Kasir'!$A:$A, $A16, 'Drop Data Kasir'!$C:$C, Z$5) -> 1 | AA16: =SUMIFS('Drop Data Kasir'!$B:$B, 'Drop Data Kasir'!$A:$A, $A16, 'Drop Data Kasir'!$C:$C, AA$5) -> 0 | AB16: =SUMIFS('Drop Data Kasir'!$B:$B, 'Drop Data Kasir'!$A:$A, $A16, 'Drop Data Kasir'!$C:$C, AB$5) -> 4 | AC16: =SUMIFS('Drop Data Kasir'!$B:$B, 'Drop Data Kasir'!$A:$A, $A16, 'Drop Data Kasir'!$C:$C, AC$5) -> 1 | AD16: =SUMIFS('Drop Data Kasir'!$B:$B, 'Drop Data Kasir'!$A:$A, $A16, 'Drop Data Kasir'!$C:$C, AD$5) -> 2 | AE16: =SUMIFS('Drop Data Kasir'!$B:$B, 'Drop Data Kasir'!$A:$A, $A16, 'Drop Data Kasir'!$C:$C, AE$5) -> 1 | ... AG16: =SUMIFS('Drop Data Kasir'!$B:$B, 'Drop Data Kasir'!$A:$A, $A16, 'Drop Data Kasir'!$C:$C, AG$5) -> 0
A17: =IFERROR(__xludf.DUMMYFUNCTION("""COMPUTED_VALUE"""),"Air mineral besar") -> Air mineral besar | B17: =IFERROR(__xludf.DUMMYFUNCTION("""COMPUTED_VALUE"""),17500.0) -> 17500 | C17: 14 | D17: 0 | E17: 0 | F17: 4 | G17: 8 | H17: 11 | I17: 8 | J17: 3 | K17: 0 | L17: 0 | M17: 11 | N17: 4 | O17: 1 | P17: 2 | Q17: 3 | R17: 6 | S17: 2 | T17: 4 | U17: 2 | V17: 4 | W17: 7 | X17: =SUMIFS('Drop Data Kasir'!$B:$B, 'Drop Data Kasir'!$A:$A, $A17, 'Drop Data Kasir'!$C:$C, X$5) -> 1 | Y17: =SUMIFS('Drop Data Kasir'!$B:$B, 'Drop Data Kasir'!$A:$A, $A17, 'Drop Data Kasir'!$C:$C, Y$5) -> 8 | Z17: =SUMIFS('Drop Data Kasir'!$B:$B, 'Drop Data Kasir'!$A:$A, $A17, 'Drop Data Kasir'!$C:$C, Z$5) -> 1 | AA17: =SUMIFS('Drop Data Kasir'!$B:$B, 'Drop Data Kasir'!$A:$A, $A17, 'Drop Data Kasir'!$C:$C, AA$5) -> 3 | AB17: =SUMIFS('Drop Data Kasir'!$B:$B, 'Drop Data Kasir'!$A:$A, $A17, 'Drop Data Kasir'!$C:$C, AB$5) -> 9 | AC17: =SUMIFS('Drop Data Kasir'!$B:$B, 'Drop Data Kasir'!$A:$A, $A17, 'Drop Data Kasir'!$C:$C, AC$5) -> 10 | AD17: =SUMIFS('Drop Data Kasir'!$B:$B, 'Drop Data Kasir'!$A:$A, $A17, 'Drop Data Kasir'!$C:$C, AD$5) -> 1 | AE17: =SUMIFS('Drop Data Kasir'!$B:$B, 'Drop Data Kasir'!$A:$A, $A17, 'Drop Data Kasir'!$C:$C, AE$5) -> 2 | ... AG17: =SUMIFS('Drop Data Kasir'!$B:$B, 'Drop Data Kasir'!$A:$A, $A17, 'Drop Data Kasir'!$C:$C, AG$5) -> 0
A18: =IFERROR(__xludf.DUMMYFUNCTION("""COMPUTED_VALUE"""),"Teh Belanda") -> Teh Belanda | B18: =IFERROR(__xludf.DUMMYFUNCTION("""COMPUTED_VALUE"""),13500.0) -> 13500 | C18: 14 | D18: 0 | E18: 11 | F18: 4 | G18: 3 | H18: 2 | I18: 0 | J18: 1 | K18: 0 | L18: 0 | M18: 2 | N18: 0 | O18: 3 | P18: 2 | Q18: 1 | R18: 0 | S18: 12 | T18: 1 | U18: 1 | V18: 3 | W18: 0 | X18: =SUMIFS('Drop Data Kasir'!$B:$B, 'Drop Data Kasir'!$A:$A, $A18, 'Drop Data Kasir'!$C:$C, X$5) -> 3 | Y18: =SUMIFS('Drop Data Kasir'!$B:$B, 'Drop Data Kasir'!$A:$A, $A18, 'Drop Data Kasir'!$C:$C, Y$5) -> 0 | Z18: =SUMIFS('Drop Data Kasir'!$B:$B, 'Drop Data Kasir'!$A:$A, $A18, 'Drop Data Kasir'!$C:$C, Z$5) -> 0 | AA18: =SUMIFS('Drop Data Kasir'!$B:$B, 'Drop Data Kasir'!$A:$A, $A18, 'Drop Data Kasir'!$C:$C, AA$5) -> 2 | AB18: =SUMIFS('Drop Data Kasir'!$B:$B, 'Drop Data Kasir'!$A:$A, $A18, 'Drop Data Kasir'!$C:$C, AB$5) -> 1 | AC18: =SUMIFS('Drop Data Kasir'!$B:$B, 'Drop Data Kasir'!$A:$A, $A18, 'Drop Data Kasir'!$C:$C, AC$5) -> 2 | AD18: =SUMIFS('Drop Data Kasir'!$B:$B, 'Drop Data Kasir'!$A:$A, $A18, 'Drop Data Kasir'!$C:$C, AD$5) -> 0 | AE18: =SUMIFS('Drop Data Kasir'!$B:$B, 'Drop Data Kasir'!$A:$A, $A18, 'Drop Data Kasir'!$C:$C, AE$5) -> 0 | ... AG18: =SUMIFS('Drop Data Kasir'!$B:$B, 'Drop Data Kasir'!$A:$A, $A18, 'Drop Data Kasir'!$C:$C, AG$5) -> 0
A19: =IFERROR(__xludf.DUMMYFUNCTION("""COMPUTED_VALUE"""),"Sunny Beach") -> Sunny Beach | B19: =IFERROR(__xludf.DUMMYFUNCTION("""COMPUTED_VALUE"""),25000.0) -> 25000 | C19: 13 | D19: 0 | E19: 0 | F19: 5 | G19: 3 | H19: 0 | I19: 0 | J19: 0 | K19: 1 | L19: 1 | M19: 3 | N19: 1 | O19: 1 | P19: 2 | Q19: 0 | R19: 1 | S19: 0 | T19: 3 | U19: 0 | V19: 1 | W19: 0 | X19: =SUMIFS('Drop Data Kasir'!$B:$B, 'Drop Data Kasir'!$A:$A, $A19, 'Drop Data Kasir'!$C:$C, X$5) -> 1 | Y19: =SUMIFS('Drop Data Kasir'!$B:$B, 'Drop Data Kasir'!$A:$A, $A19, 'Drop Data Kasir'!$C:$C, Y$5) -> 0 | Z19: =SUMIFS('Drop Data Kasir'!$B:$B, 'Drop Data Kasir'!$A:$A, $A19, 'Drop Data Kasir'!$C:$C, Z$5) -> 0 | AA19: =SUMIFS('Drop Data Kasir'!$B:$B, 'Drop Data Kasir'!$A:$A, $A19, 'Drop Data Kasir'!$C:$C, AA$5) -> 0 | AB19: =SUMIFS('Drop Data Kasir'!$B:$B, 'Drop Data Kasir'!$A:$A, $A19, 'Drop Data Kasir'!$C:$C, AB$5) -> 4 | AC19: =SUMIFS('Drop Data Kasir'!$B:$B, 'Drop Data Kasir'!$A:$A, $A19, 'Drop Data Kasir'!$C:$C, AC$5) -> 1 | AD19: =SUMIFS('Drop Data Kasir'!$B:$B, 'Drop Data Kasir'!$A:$A, $A19, 'Drop Data Kasir'!$C:$C, AD$5) -> 0 | AE19: =SUMIFS('Drop Data Kasir'!$B:$B, 'Drop Data Kasir'!$A:$A, $A19, 'Drop Data Kasir'!$C:$C, AE$5) -> 0 | ... AG19: =SUMIFS('Drop Data Kasir'!$B:$B, 'Drop Data Kasir'!$A:$A, $A19, 'Drop Data Kasir'!$C:$C, AG$5) -> 0
A20: =IFERROR(__xludf.DUMMYFUNCTION("""COMPUTED_VALUE"""),"Air mineral") -> Air mineral | B20: =IFERROR(__xludf.DUMMYFUNCTION("""COMPUTED_VALUE"""),8000.0) -> 8000 | C20: 12 | D20: 0 | E20: 0 | F20: 0 | G20: 0 | H20: 0 | I20: 0 | J20: 1 | K20: 0 | L20: 0 | M20: 0 | N20: 0 | O20: 0 | P20: 0 | Q20: 0 | R20: 0 | S20: 0 | T20: 0 | U20: 0 | V20: 0 | W20: 0 | X20: =SUMIFS('Drop Data Kasir'!$B:$B, 'Drop Data Kasir'!$A:$A, $A20, 'Drop Data Kasir'!$C:$C, X$5) -> 0 | Y20: =SUMIFS('Drop Data Kasir'!$B:$B, 'Drop Data Kasir'!$A:$A, $A20, 'Drop Data Kasir'!$C:$C, Y$5) -> 0 | Z20: =SUMIFS('Drop Data Kasir'!$B:$B, 'Drop Data Kasir'!$A:$A, $A20, 'Drop Data Kasir'!$C:$C, Z$5) -> 0 | AA20: =SUMIFS('Drop Data Kasir'!$B:$B, 'Drop Data Kasir'!$A:$A, $A20, 'Drop Data Kasir'!$C:$C, AA$5) -> 0 | AB20: =SUMIFS('Drop Data Kasir'!$B:$B, 'Drop Data Kasir'!$A:$A, $A20, 'Drop Data Kasir'!$C:$C, AB$5) -> 0 | AC20: =SUMIFS('Drop Data Kasir'!$B:$B, 'Drop Data Kasir'!$A:$A, $A20, 'Drop Data Kasir'!$C:$C, AC$5) -> 0 | AD20: =SUMIFS('Drop Data Kasir'!$B:$B, 'Drop Data Kasir'!$A:$A, $A20, 'Drop Data Kasir'!$C:$C, AD$5) -> 0 | AE20: =SUMIFS('Drop Data Kasir'!$B:$B, 'Drop Data Kasir'!$A:$A, $A20, 'Drop Data Kasir'!$C:$C, AE$5) -> 0 | ... AG20: =SUMIFS('Drop Data Kasir'!$B:$B, 'Drop Data Kasir'!$A:$A, $A20, 'Drop Data Kasir'!$C:$C, AG$5) -> 0
A21: =IFERROR(__xludf.DUMMYFUNCTION("""COMPUTED_VALUE"""),"Kopi Nenek") -> Kopi Nenek | B21: =IFERROR(__xludf.DUMMYFUNCTION("""COMPUTED_VALUE"""),9000.0) -> 9000 | C21: 12 | D21: 0 | E21: 1 | F21: 4 | G21: 3 | H21: 1 | I21: 3 | J21: 6 | K21: 0 | L21: 0 | M21: 5 | N21: 0 | O21: 0 | P21: 0 | Q21: 0 | R21: 3 | S21: 1 | T21: 1 | U21: 1 | V21: 0 | W21: 0 | X21: =SUMIFS('Drop Data Kasir'!$B:$B, 'Drop Data Kasir'!$A:$A, $A21, 'Drop Data Kasir'!$C:$C, X$5) -> 0 | Y21: =SUMIFS('Drop Data Kasir'!$B:$B, 'Drop Data Kasir'!$A:$A, $A21, 'Drop Data Kasir'!$C:$C, Y$5) -> 0 | Z21: =SUMIFS('Drop Data Kasir'!$B:$B, 'Drop Data Kasir'!$A:$A, $A21, 'Drop Data Kasir'!$C:$C, Z$5) -> 0 | AA21: =SUMIFS('Drop Data Kasir'!$B:$B, 'Drop Data Kasir'!$A:$A, $A21, 'Drop Data Kasir'!$C:$C, AA$5) -> 5 | AB21: =SUMIFS('Drop Data Kasir'!$B:$B, 'Drop Data Kasir'!$A:$A, $A21, 'Drop Data Kasir'!$C:$C, AB$5) -> 5 | AC21: =SUMIFS('Drop Data Kasir'!$B:$B, 'Drop Data Kasir'!$A:$A, $A21, 'Drop Data Kasir'!$C:$C, AC$5) -> 0 | AD21: =SUMIFS('Drop Data Kasir'!$B:$B, 'Drop Data Kasir'!$A:$A, $A21, 'Drop Data Kasir'!$C:$C, AD$5) -> 2 | AE21: =SUMIFS('Drop Data Kasir'!$B:$B, 'Drop Data Kasir'!$A:$A, $A21, 'Drop Data Kasir'!$C:$C, AE$5) -> 3 | ... AG21: =SUMIFS('Drop Data Kasir'!$B:$B, 'Drop Data Kasir'!$A:$A, $A21, 'Drop Data Kasir'!$C:$C, AG$5) -> 0
A22: =IFERROR(__xludf.DUMMYFUNCTION("""COMPUTED_VALUE"""),"Wedang uwuh Ngawi") -> Wedang uwuh Ngawi | B22: =IFERROR(__xludf.DUMMYFUNCTION("""COMPUTED_VALUE"""),13000.0) -> 13000 | C22: 10 | D22: 0 | E22: 7 | F22: 1 | G22: 0 | H22: 0 | I22: 0 | J22: 0 | K22: 0 | L22: 0 | M22: 0 | N22: 0 | O22: 1 | P22: 0 | Q22: 0 | R22: 0 | S22: 0 | T22: 1 | U22: 0 | V22: 0 | W22: 0 | X22: =SUMIFS('Drop Data Kasir'!$B:$B, 'Drop Data Kasir'!$A:$A, $A22, 'Drop Data Kasir'!$C:$C, X$5) -> 0 | Y22: =SUMIFS('Drop Data Kasir'!$B:$B, 'Drop Data Kasir'!$A:$A, $A22, 'Drop Data Kasir'!$C:$C, Y$5) -> 0 | Z22: =SUMIFS('Drop Data Kasir'!$B:$B, 'Drop Data Kasir'!$A:$A, $A22, 'Drop Data Kasir'!$C:$C, Z$5) -> 0 | AA22: =SUMIFS('Drop Data Kasir'!$B:$B, 'Drop Data Kasir'!$A:$A, $A22, 'Drop Data Kasir'!$C:$C, AA$5) -> 0 | AB22: =SUMIFS('Drop Data Kasir'!$B:$B, 'Drop Data Kasir'!$A:$A, $A22, 'Drop Data Kasir'!$C:$C, AB$5) -> 0 | AC22: =SUMIFS('Drop Data Kasir'!$B:$B, 'Drop Data Kasir'!$A:$A, $A22, 'Drop Data Kasir'!$C:$C, AC$5) -> 0 | AD22: =SUMIFS('Drop Data Kasir'!$B:$B, 'Drop Data Kasir'!$A:$A, $A22, 'Drop Data Kasir'!$C:$C, AD$5) -> 0 | AE22: =SUMIFS('Drop Data Kasir'!$B:$B, 'Drop Data Kasir'!$A:$A, $A22, 'Drop Data Kasir'!$C:$C, AE$5) -> 0 | ... AG22: =SUMIFS('Drop Data Kasir'!$B:$B, 'Drop Data Kasir'!$A:$A, $A22, 'Drop Data Kasir'!$C:$C, AG$5) -> 0
A23: =IFERROR(__xludf.DUMMYFUNCTION("""COMPUTED_VALUE"""),"Curly Fries") -> Curly Fries | B23: =IFERROR(__xludf.DUMMYFUNCTION("""COMPUTED_VALUE"""),22000.0) -> 22000 | C23: 9 | D23: 0 | E23: 1 | F23: 3 | G23: 3 | H23: 3 | I23: 3 | J23: 3 | K23: 1 | L23: 3 | M23: 2 | N23: 3 | O23: 2 | P23: 5 | Q23: 1 | R23: 0 | S23: 4 | T23: 3 | U23: 7 | V23: 1 | W23: 3 | X23: =SUMIFS('Drop Data Kasir'!$B:$B, 'Drop Data Kasir'!$A:$A, $A23, 'Drop Data Kasir'!$C:$C, X$5) -> 1 | Y23: =SUMIFS('Drop Data Kasir'!$B:$B, 'Drop Data Kasir'!$A:$A, $A23, 'Drop Data Kasir'!$C:$C, Y$5) -> 1 | Z23: =SUMIFS('Drop Data Kasir'!$B:$B, 'Drop Data Kasir'!$A:$A, $A23, 'Drop Data Kasir'!$C:$C, Z$5) -> 1 | AA23: =SUMIFS('Drop Data Kasir'!$B:$B, 'Drop Data Kasir'!$A:$A, $A23, 'Drop Data Kasir'!$C:$C, AA$5) -> 4 | AB23: =SUMIFS('Drop Data Kasir'!$B:$B, 'Drop Data Kasir'!$A:$A, $A23, 'Drop Data Kasir'!$C:$C, AB$5) -> 1 | AC23: =SUMIFS('Drop Data Kasir'!$B:$B, 'Drop Data Kasir'!$A:$A, $A23, 'Drop Data Kasir'!$C:$C, AC$5) -> 6 | AD23: =SUMIFS('Drop Data Kasir'!$B:$B, 'Drop Data Kasir'!$A:$A, $A23, 'Drop Data Kasir'!$C:$C, AD$5) -> 3 | AE23: =SUMIFS('Drop Data Kasir'!$B:$B, 'Drop Data Kasir'!$A:$A, $A23, 'Drop Data Kasir'!$C:$C, AE$5) -> 1 | ... AG23: =SUMIFS('Drop Data Kasir'!$B:$B, 'Drop Data Kasir'!$A:$A, $A23, 'Drop Data Kasir'!$C:$C, AG$5) -> 0
A24: =IFERROR(__xludf.DUMMYFUNCTION("""COMPUTED_VALUE"""),"Hongkong Soft Tale") -> Hongkong Soft Tale | B24: =IFERROR(__xludf.DUMMYFUNCTION("""COMPUTED_VALUE"""),21000.0) -> 21000 | C24: 8 | D24: 0 | E24: 0 | F24: 1 | G24: 3 | H24: 1 | I24: 0 | J24: 1 | K24: 0 | L24: 0 | M24: 2 | N24: 0 | O24: 0 | P24: 1 | Q24: 1 | R24: 2 | S24: 0 | T24: 0 | U24: 1 | V24: 1 | W24: 0 | X24: =SUMIFS('Drop Data Kasir'!$B:$B, 'Drop Data Kasir'!$A:$A, $A24, 'Drop Data Kasir'!$C:$C, X$5) -> 0 | Y24: =SUMIFS('Drop Data Kasir'!$B:$B, 'Drop Data Kasir'!$A:$A, $A24, 'Drop Data Kasir'!$C:$C, Y$5) -> 0 | Z24: =SUMIFS('Drop Data Kasir'!$B:$B, 'Drop Data Kasir'!$A:$A, $A24, 'Drop Data Kasir'!$C:$C, Z$5) -> 0 | AA24: =SUMIFS('Drop Data Kasir'!$B:$B, 'Drop Data Kasir'!$A:$A, $A24, 'Drop Data Kasir'!$C:$C, AA$5) -> 0 | AB24: =SUMIFS('Drop Data Kasir'!$B:$B, 'Drop Data Kasir'!$A:$A, $A24, 'Drop Data Kasir'!$C:$C, AB$5) -> 2 | AC24: =SUMIFS('Drop Data Kasir'!$B:$B, 'Drop Data Kasir'!$A:$A, $A24, 'Drop Data Kasir'!$C:$C, AC$5) -> 1 | AD24: =SUMIFS('Drop Data Kasir'!$B:$B, 'Drop Data Kasir'!$A:$A, $A24, 'Drop Data Kasir'!$C:$C, AD$5) -> 0 | AE24: =SUMIFS('Drop Data Kasir'!$B:$B, 'Drop Data Kasir'!$A:$A, $A24, 'Drop Data Kasir'!$C:$C, AE$5) -> 0 | ... AG24: =SUMIFS('Drop Data Kasir'!$B:$B, 'Drop Data Kasir'!$A:$A, $A24, 'Drop Data Kasir'!$C:$C, AG$5) -> 0
A25: =IFERROR(__xludf.DUMMYFUNCTION("""COMPUTED_VALUE"""),"Jong Java") -> Jong Java | B25: =IFERROR(__xludf.DUMMYFUNCTION("""COMPUTED_VALUE"""),21000.0) -> 21000 | C25: 8 | D25: 0 | E25: 0 | F25: 1 | G25: 2 | H25: 4 | I25: 0 | J25: 0 | K25: 1 | L25: 2 | M25: 1 | N25: 0 | O25: 0 | P25: 1 | Q25: 1 | R25: 1 | S25: 0 | T25: 2 | U25: 0 | V25: 3 | W25: 2 | X25: =SUMIFS('Drop Data Kasir'!$B:$B, 'Drop Data Kasir'!$A:$A, $A25, 'Drop Data Kasir'!$C:$C, X$5) -> 0 | Y25: =SUMIFS('Drop Data Kasir'!$B:$B, 'Drop Data Kasir'!$A:$A, $A25, 'Drop Data Kasir'!$C:$C, Y$5) -> 0 | Z25: =SUMIFS('Drop Data Kasir'!$B:$B, 'Drop Data Kasir'!$A:$A, $A25, 'Drop Data Kasir'!$C:$C, Z$5) -> 0 | AA25: =SUMIFS('Drop Data Kasir'!$B:$B, 'Drop Data Kasir'!$A:$A, $A25, 'Drop Data Kasir'!$C:$C, AA$5) -> 1 | AB25: =SUMIFS('Drop Data Kasir'!$B:$B, 'Drop Data Kasir'!$A:$A, $A25, 'Drop Data Kasir'!$C:$C, AB$5) -> 0 | AC25: =SUMIFS('Drop Data Kasir'!$B:$B, 'Drop Data Kasir'!$A:$A, $A25, 'Drop Data Kasir'!$C:$C, AC$5) -> 1 | AD25: =SUMIFS('Drop Data Kasir'!$B:$B, 'Drop Data Kasir'!$A:$A, $A25, 'Drop Data Kasir'!$C:$C, AD$5) -> 0 | AE25: =SUMIFS('Drop Data Kasir'!$B:$B, 'Drop Data Kasir'!$A:$A, $A25, 'Drop Data Kasir'!$C:$C, AE$5) -> 0 | ... AG25: =SUMIFS('Drop Data Kasir'!$B:$B, 'Drop Data Kasir'!$A:$A, $A25, 'Drop Data Kasir'!$C:$C, AG$5) -> 0
